Workbook
Name _____________________MHA1: {"rtn",#N/A,FALSE,"RTN";"tables",#N/A,FALSE,"RTN";"cf",#N/A,FALSE,"CF";"stats",#N/A,FALSE,"Stats";"prop",#N/A,FALSE,"Prop"}
Name _____________________T123456: {"COUNT",#N/A,FALSE,"AB"}
Name _____________________T12347: {"COUNT",#N/A,FALSE,"AB"}
Name __________________T123456: {"COUNT",#N/A,FALSE,"AB"}
Name __________________T12347: {"COUNT",#N/A,FALSE,"AB"}
Name ________________MHA1: {"rtn",#N/A,FALSE,"RTN";"tables",#N/A,FALSE,"RTN";"cf",#N/A,FALSE,"CF";"stats",#N/A,FALSE,"Stats";"prop",#N/A,FALSE,"Prop"}
Name ______________T123456: {"COUNT",#N/A,FALSE,"AB"}
Name ______________T12347: {"COUNT",#N/A,FALSE,"AB"}
Name _____________MHA1: {"rtn",#N/A,FALSE,"RTN";"tables",#N/A,FALSE,"RTN";"cf",#N/A,FALSE,"CF";"stats",#N/A,FALSE,"Stats";"prop",#N/A,FALSE,"Prop"}
Name ___________MHA1: {"rtn",#N/A,FALSE,"RTN";"tables",#N/A,FALSE,"RTN";"cf",#N/A,FALSE,"CF";"stats",#N/A,FALSE,"Stats";"prop",#N/A,FALSE,"Prop"}
Name __________MHA1: {"rtn",#N/A,FALSE,"RTN";"tables",#N/A,FALSE,"RTN";"cf",#N/A,FALSE,"CF";"stats",#N/A,FALSE,"Stats";"prop",#N/A,FALSE,"Prop"}
Name _________MHA1: {"rtn",#N/A,FALSE,"RTN";"tables",#N/A,FALSE,"RTN";"cf",#N/A,FALSE,"CF";"stats",#N/A,FALSE,"Stats";"prop",#N/A,FALSE,"Prop"}
Name _________MHA1_1: {"rtn",#N/A,FALSE,"RTN";"tables",#N/A,FALSE,"RTN";"cf",#N/A,FALSE,"CF";"stats",#N/A,FALSE,"Stats";"prop",#N/A,FALSE,"Prop"}
Name ________MHA1: {"rtn",#N/A,FALSE,"RTN";"tables",#N/A,FALSE,"RTN";"cf",#N/A,FALSE,"CF";"stats",#N/A,FALSE,"Stats";"prop",#N/A,FALSE,"Prop"}
Name ________MHA1_1: {"rtn",#N/A,FALSE,"RTN";"tables",#N/A,FALSE,"RTN";"cf",#N/A,FALSE,"CF";"stats",#N/A,FALSE,"Stats";"prop",#N/A,FALSE,"Prop"}
Name _______MHA1: {"rtn",#N/A,FALSE,"RTN";"tables",#N/A,FALSE,"RTN";"cf",#N/A,FALSE,"CF";"stats",#N/A,FALSE,"Stats";"prop",#N/A,FALSE,"Prop"}
Name _______MHA1_1: {"rtn",#N/A,FALSE,"RTN";"tables",#N/A,FALSE,"RTN";"cf",#N/A,FALSE,"CF";"stats",#N/A,FALSE,"Stats";"prop",#N/A,FALSE,"Prop"}
Name _______T123456: {"COUNT",#N/A,FALSE,"AB"}
Name _______T12347: {"COUNT",#N/A,FALSE,"AB"}
Name ______MHA1: {"rtn",#N/A,FALSE,"RTN";"tables",#N/A,FALSE,"RTN";"cf",#N/A,FALSE,"CF";"stats",#N/A,FALSE,"Stats";"prop",#N/A,FALSE,"Prop"}
Name ______MHA1_1: {"rtn",#N/A,FALSE,"RTN";"tables",#N/A,FALSE,"RTN";"cf",#N/A,FALSE,"CF";"stats",#N/A,FALSE,"Stats";"prop",#N/A,FALSE,"Prop"}
Name _____DF4: #REF!
Name _____MHA1: {"rtn",#N/A,FALSE,"RTN";"tables",#N/A,FALSE,"RTN";"cf",#N/A,FALSE,"CF";"stats",#N/A,FALSE,"Stats";"prop",#N/A,FALSE,"Prop"}
Name _____MHA1_1: {"rtn",#N/A,FALSE,"RTN";"tables",#N/A,FALSE,"RTN";"cf",#N/A,FALSE,"CF";"stats",#N/A,FALSE,"Stats";"prop",#N/A,FALSE,"Prop"}
Name _____New2: {"TOTAL",#N/A,FALSE,"A";"FISCAL94",#N/A,FALSE,"A";"FISCAL95",#N/A,FALSE,"A";"FISCAL96",#N/A,FALSE,"A";"misc page",#N/A,FALSE,"A"}
Name _____R: {#N/A,#N/A,FALSE,"Minors";#N/A,#N/A,FALSE,"96CAPREV"}
Name _____T123456: {"COUNT",#N/A,FALSE,"AB"}
Name _____T12347: {"COUNT",#N/A,FALSE,"AB"}
Name ____DCF2: {#N/A,#N/A,TRUE,"DCF Summary (2)";#N/A,#N/A,TRUE,"DCF Summary";#N/A,"Middle Case Drivers",TRUE,"DCF"}
Name ____DF4: #REF!
Name ____JLC1: {#N/A,#N/A,TRUE,"97plnfpg"}
Name ____JLC3: {#N/A,#N/A,FALSE,"J97plnfp"}
Name ____MHA1: {"rtn",#N/A,FALSE,"RTN";"tables",#N/A,FALSE,"RTN";"cf",#N/A,FALSE,"CF";"stats",#N/A,FALSE,"Stats";"prop",#N/A,FALSE,"Prop"}
Name ____MHA1_1: {"rtn",#N/A,FALSE,"RTN";"tables",#N/A,FALSE,"RTN";"cf",#N/A,FALSE,"CF";"stats",#N/A,FALSE,"Stats";"prop",#N/A,FALSE,"Prop"}
Name ____New2: {"TOTAL",#N/A,FALSE,"A";"FISCAL94",#N/A,FALSE,"A";"FISCAL95",#N/A,FALSE,"A";"FISCAL96",#N/A,FALSE,"A";"misc page",#N/A,FALSE,"A"}
Name ____R: {#N/A,#N/A,FALSE,"Minors";#N/A,#N/A,FALSE,"96CAPREV"}
Name ____T123456: {"COUNT",#N/A,FALSE,"AB"}
Name ____T12347: {"COUNT",#N/A,FALSE,"AB"}
Name ____wrn2: {#N/A,#N/A,FALSE,"ASSUMPTIONS";#N/A,#N/A,FALSE,"Valuation Summary";"page1",#N/A,FALSE,"PRESENTATION";"page2",#N/A,FALSE,"PRESENTATION";#N/A,#N/A,FALSE,"ORIGINAL_ROLLBACK"}
Name ____wrn3: {#N/A,#N/A,FALSE,"ASSUMPTIONS";#N/A,#N/A,FALSE,"Valuation Summary";"page1",#N/A,FALSE,"PRESENTATION";"page2",#N/A,FALSE,"PRESENTATION";#N/A,#N/A,FALSE,"ORIGINAL_ROLLBACK"}
Name ___aaa1: {#N/A,#N/A,FALSE,"Model";#N/A,#N/A,FALSE,"Division"}
Name ___c: {#N/A,#N/A,FALSE,"Layout Cash Flow"}
Name ___DCF2: {#N/A,#N/A,TRUE,"DCF Summary (2)";#N/A,#N/A,TRUE,"DCF Summary";#N/A,"Middle Case Drivers",TRUE,"DCF"}
Name ___DF4: #REF!
Name ___fy97: {#N/A,#N/A,FALSE,"FY97";#N/A,#N/A,FALSE,"FY98";#N/A,#N/A,FALSE,"FY99";#N/A,#N/A,FALSE,"FY00";#N/A,#N/A,FALSE,"FY01"}
Name ___key2: #REF!
Name ___MHA1: {"rtn",#N/A,FALSE,"RTN";"tables",#N/A,FALSE,"RTN";"cf",#N/A,FALSE,"CF";"stats",#N/A,FALSE,"Stats";"prop",#N/A,FALSE,"Prop"}
Name ___MHA1_1: {"rtn",#N/A,FALSE,"RTN";"tables",#N/A,FALSE,"RTN";"cf",#N/A,FALSE,"CF";"stats",#N/A,FALSE,"Stats";"prop",#N/A,FALSE,"Prop"}
Name ___New2: {"TOTAL",#N/A,FALSE,"A";"FISCAL94",#N/A,FALSE,"A";"FISCAL95",#N/A,FALSE,"A";"FISCAL96",#N/A,FALSE,"A";"misc page",#N/A,FALSE,"A"}
Name ___r: {"consolidated",#N/A,FALSE,"Sheet1";"cms",#N/A,FALSE,"Sheet1";"fse",#N/A,FALSE,"Sheet1"}
Name ___T12347: {"COUNT",#N/A,FALSE,"AB"}
Name ___wrn1: {#N/A,#N/A,FALSE,"DCF";#N/A,#N/A,FALSE,"WACC";#N/A,#N/A,FALSE,"Sales_EBIT";#N/A,#N/A,FALSE,"Capex_Depreciation";#N/A,#N/A,FALSE,"WC";#N/A,#N/A,FALSE,"Interest";#N/A,#N/A,FALSE,"Assumptions"}
Name __1__123Graph_ACHART_1: #REF!
Name __10__123Graph_CCHART_3: #REF!
Name __11__123Graph_CCHART_8: #REF!
Name __12__123Graph_DCHART_1: #REF!
Name __123Graph_A: #REF!
Name __123Graph_AANIDRO: #REF!
Name __123Graph_AAPPIP: #REF!
Name __123Graph_AB06: #REF!

Sheet Cover
B5: Financial Databook
B7: Table of Contents:
B8: Summary
B9: Income Statement
B10: Calculations
B11: Revenue_Calcs
B12: COGS_Calcs
B13: Opex_Calcs
B14: Bookings to Revenue_Calcs
B15: Assumptions
B16: Revenue_Assumptions
B17: COGS_Assumptions
B18: Opex_Assumptions
B20: As of: | C20: 44286

Sheet Summary
B2: Summary Income Statement | H2: 2022 Run-Rate
B3: ($ in millions) | D3: 2019 | E3: =+D3+1 | F3: =+E3+1 | G3: =+F3+1 | H3: Run-Rate | I3: =+G3+1 | J3: =+I3+1 | K3: =+J3+1 | L3: =+K3+1
B5: =+'Income Statement'!B12 | D5: =+'Income Statement'!F12/10^3 | E5: =+'Income Statement'!G12/10^3 | F5: =+'Income Statement'!H12/10^3 | G5: =+'Income Statement'!I12/10^3 | H5: =+'Income Statement'!O12/10^3 | I5: =+'Income Statement'!J12/10^3 | J5: =+'Income Statement'!K12/10^3 | K5: =+'Income Statement'!L12/10^3 | L5: =+'Income Statement'!M12/10^3
B6: =+'Income Statement'!B13 | D6: =+'Income Statement'!F13/10^3 | E6: =+'Income Statement'!G13/10^3 | F6: =+'Income Statement'!H13/10^3 | G6: =+'Income Statement'!I13/10^3 | H6: =+'Income Statement'!O13/10^3 | I6: =+'Income Statement'!J13/10^3 | J6: =+'Income Statement'!K13/10^3 | K6: =+'Income Statement'!L13/10^3 | L6: =+'Income Statement'!M13/10^3
B7: =+'Income Statement'!B14 | D7: =+'Income Statement'!F14/10^3 | E7: =+'Income Statement'!G14/10^3 | F7: =+'Income Statement'!H14/10^3 | G7: =+'Income Statement'!I14/10^3 | H7: =+'Income Statement'!O14/10^3 | I7: =+'Income Statement'!J14/10^3 | J7: =+'Income Statement'!K14/10^3 | K7: =+'Income Statement'!L14/10^3 | L7: =+'Income Statement'!M14/10^3
B8: =+'Income Statement'!B15 | D8: =+'Income Statement'!F15/10^3 | E8: =+'Income Statement'!G15/10^3 | F8: =+'Income Statement'!H15/10^3 | G8: =+'Income Statement'!I15/10^3 | H8: =+'Income Statement'!O15/10^3 | I8: =+'Income Statement'!J15/10^3 | J8: =+'Income Statement'!K15/10^3 | K8: =+'Income Statement'!L15/10^3 | L8: =+'Income Statement'!M15/10^3
B9: =+'Income Statement'!B16 | D9: =+'Income Statement'!F16/10^3 | E9: =+'Income Statement'!G16/10^3 | F9: =+'Income Statement'!H16/10^3 | G9: =+'Income Statement'!I16/10^3 | H9: =+'Income Statement'!O16/10^3 | I9: =+'Income Statement'!J16/10^3 | J9: =+'Income Statement'!K16/10^3 | K9: =+'Income Statement'!L16/10^3 | L9: =+'Income Statement'!M16/10^3
B10: % Growth | E10: =+E9/D9-1 | F10: =+F9/E9-1 | G10: =+G9/F9-1 | I10: =+I9/G9-1 | J10: =+J9/I9-1 | K10: =+K9/J9-1 | L10: =+L9/K9-1
B12: Cost of Sales | D12: =+'Income Statement'!F22/10^3 | E12: =+'Income Statement'!G22/10^3 | F12: =+'Income Statement'!H22/10^3 | G12: =+'Income Statement'!I22/10^3 | H12: =+'Income Statement'!O22/10^3 | I12: =+'Income Statement'!J22/10^3 | J12: =+'Income Statement'!K22/10^3 | K12: =+'Income Statement'!L22/10^3 | L12: =+'Income Statement'!M22/10^3
B13: Gross Profit | D13: =+D9-D12 | E13: =+E9-E12 | F13: =+F9-F12 | G13: =+G9-G12 | H13: =+H9-H12 | I13: =+I9-I12 | J13: =+J9-J12 | K13: =+K9-K12 | L13: =+L9-L12
B14: % Gross Margin | D14: =+D13/D$9 | E14: =+E13/E$9 | F14: =+F13/F$9 | G14: =+G13/G$9 | H14: =+H13/H$9 | I14: =+I13/I$9 | J14: =+J13/J$9 | K14: =+K13/K$9 | L14: =+L13/L$9
B16: =+'Income Statement'!B27 | D16: =+'Income Statement'!F27/10^3 | E16: =+'Income Statement'!G27/10^3 | F16: =+'Income Statement'!H27/10^3 | G16: =+'Income Statement'!I27/10^3 | H16: =+'Income Statement'!O27/10^3 | I16: =+'Income Statement'!J27/10^3 | J16: =+'Income Statement'!K27/10^3 | K16: =+'Income Statement'!L27/10^3 | L16: =+'Income Statement'!M27/10^3
B17: Rent | D17: =+'Income Statement'!F28/10^3 | E17: =+'Income Statement'!G28/10^3 | F17: =+'Income Statement'!H28/10^3 | G17: =+'Income Statement'!I28/10^3 | H17: =+'Income Statement'!O28/10^3 | I17: =+'Income Statement'!J28/10^3 | J17: =+'Income Statement'!K28/10^3 | K17: =+'Income Statement'!L28/10^3 | L17: =+'Income Statement'!M28/10^3
B18: Sales & Marketing | D18: =+'Income Statement'!F30/10^3 | E18: =+'Income Statement'!G30/10^3 | F18: =+'Income Statement'!H30/10^3 | G18: =+'Income Statement'!I30/10^3 | H18: =+'Income Statement'!O30/10^3 | I18: =+'Income Statement'!J30/10^3 | J18: =+'Income Statement'!K30/10^3 | K18: =+'Income Statement'!L30/10^3 | L18: =+'Income Statement'!M30/10^3
B19: Other Opex | D19: =+SUM('Income Statement'!F29,'Income Statement'!F31:F33)/10^3 | E19: =+SUM('Income Statement'!G29,'Income Statement'!G31:G33)/10^3 | F19: =+SUM('Income Statement'!H29,'Income Statement'!H31:H33)/10^3 | G19: =+SUM('Income Statement'!I29,'Income Statement'!I31:I33)/10^3 | H19: =+SUM('Income Statement'!O29,'Income Statement'!O31:O33)/10^3 | I19: =+SUM('Income Statement'!J29,'Income Statement'!J31:J33)/10^3 | J19: =+SUM('Income Statement'!K29,'Income Statement'!K31:K33)/10^3 | K19: =+SUM('Income Statement'!L29,'Income Statement'!L31:L33)/10^3 | L19: =+SUM('Income Statement'!M29,'Income Statement'!M31:M33)/10^3
B20: Other I/E | D20: =+'Income Statement'!F35/10^3 | E20: =+'Income Statement'!G35/10^3 | F20: =+'Income Statement'!H35/10^3 | G20: =+'Income Statement'!I35/10^3 | H20: =+'Income Statement'!O35/10^3 | I20: =+'Income Statement'!J35/10^3 | J20: =+'Income Statement'!K35/10^3 | K20: =+'Income Statement'!L35/10^3 | L20: =+'Income Statement'!M35/10^3
B21: Reported EBITDA | D21: =+D13-SUM(D16:D20) | E21: =+E13-SUM(E16:E20) | F21: =+F13-SUM(F16:F20) | G21: =+G13-SUM(G16:G20) | H21: =+H13-SUM(H16:H20) | I21: =+I13-SUM(I16:I20) | J21: =+J13-SUM(J16:J20) | K21: =+K13-SUM(K16:K20) | L21: =+L13-SUM(L16:L20)
B22: % Margin | D22: =+D21/D$9 | E22: =+E21/E$9 | F22: =+F21/F$9 | G22: =+G21/G$9 | H22: =+H21/H$9 | I22: =+I21/I$9 | J22: =+J21/J$9 | K22: =+K21/K$9 | L22: =+L21/L$9
B24: Adjustments | D24: =+'Income Statement'!F48/10^3 | E24: =+'Income Statement'!G48/10^3 | F24: =+'Income Statement'!H48/10^3 | G24: =+'Income Statement'!I48/10^3 | H24: =+'Income Statement'!O48/10^3 | I24: =+'Income Statement'!J48/10^3 | J24: =+'Income Statement'!K48/10^3 | K24: =+'Income Statement'!L48/10^3 | L24: =+'Income Statement'!M48/10^3
B25: Adjusted EBITDA | D25: =+D21+D24 | E25: =+E21+E24 | F25: =+F21+F24 | G25: =+G21+G24 | H25: =+H21+H24 | I25: =+I21+I24 | J25: =+J21+J24 | K25: =+K21+K24 | L25: =+L21+L24
B26: % Margin | D26: =+D25/D$9 | E26: =+E25/E$9 | F26: =+F25/F$9 | G26: =+G25/G$9 | H26: =+H25/H$9 | I26: =+I25/I$9 | J26: =+J25/J$9 | K26: =+K25/K$9 | L26: =+L25/L$9
B27: Check | D27: =+D25-'Income Statement'!F50/10^3 | E27: =+E25-'Income Statement'!G50/10^3 | F27: =+F25-'Income Statement'!H50/10^3 | G27: =+G25-'Income Statement'!I50/10^3 | H27: =+H25-'Income Statement'!O50/10^3 | I27: =+I25-'Income Statement'!J50/10^3 | J27: =+J25-'Income Statement'!K50/10^3 | K27: =+K25-'Income Statement'!L50/10^3 | L27: =+L25-'Income Statement'!M50/10^3 | M27: =+M25-'Income Statement'!N50/10^3

Sheet Model ->

Sheet Income Statement
B2: Project Shasta
B3: {=MID(CELL("filename",A1),FIND("]",CELL("filename",A1))+1,255)}
B4: Spring 2022
B5: CONFIDENTIAL
F7: 2019 | G7: =+F7+1 | H7: =+G7+1 | I7: =+H7+1 | J7: =+I7+1 | K7: =+J7+1 | L7: =+K7+1 | M7: =+L7+1 | O7: =+I7 | Q7: =+YEAR(Q8) | R7: =+YEAR(R8) | S7: =+YEAR(S8) | T7: =+YEAR(T8) | U7: =+YEAR(U8) | V7: =+YEAR(V8) | W7: =+YEAR(W8) | X7: =+YEAR(X8) | ... DH7: =+YEAR(DH8) | DJ7: Growth / Margin Analysis
F8: =+DATE(F7,12,31) | G8: =+DATE(G7,12,31) | H8: =+DATE(H7,12,31) | I8: =+DATE(I7,12,31) | J8: =+DATE(J7,12,31) | K8: =+DATE(K7,12,31) | L8: =+DATE(L7,12,31) | M8: =+DATE(M7,12,31) | O8: =+I8 | Q8: 43496 | R8: =+EOMONTH(Q8,1) | S8: =+EOMONTH(R8,1) | T8: =+EOMONTH(S8,1) | U8: =+EOMONTH(T8,1) | V8: =+EOMONTH(U8,1) | W8: =+EOMONTH(V8,1) | X8: =+EOMONTH(W8,1) | Y8: =+EOMONTH(X8,1) | ... DH8: =+EOMONTH(DG8,1) | DJ8: 2019 | DK8: =+DJ8+1 | DL8: =+DK8+1 | DM8: =+DL8+1 | DN8: =+DM8+1 | DO8: =+DN8+1 | DP8: =+DO8+1 | DQ8: =+DP8+1
B9: $ in thousands | F9: Actual | G9: Actual | H9: Actual | I9: Budget | J9: Projection | K9: Projection | L9: Projection | M9: Projection | O9: Run Rate | Q9: Actual | R9: Actual | S9: Actual | T9: Actual | U9: Actual | V9: Actual | W9: Actual | X9: Actual | Y9: Actual | Z9: Actual | AA9: Actual | AB9: Actual | AC9: Actual | AD9: Actual | AE9: Actual | AF9: Actual | AG9: Actual | AH9: Actual | AI9: Actual | AJ9: Actual | AK9: Actual | AL9: Actual | AM9: Actual | AN9: Actual | AO9: Actual | AP9: Actual | AQ9: Actual | AR9: Actual | AS9: Actual | AT9: Actual | AU9: Actual | AV9: Actual | AW9: Actual | AX9: Actual | AY9: Actual | AZ9: Actual | BA9: Actual | BB9: Actual | BC9: Actual | BD9: Budget | BE9: Budget | BF9: Budget | BG9: Budget | BH9: Budget | BI9: Budget | BJ9: Budget | BK9: Budget | BL9: Budget | BM9: Projection | BN9: Projection | BO9: Projection | BP9: Projection | BQ9: Projection | BR9: Projection | BS9: Projection | BT9: Projection | BU9: Projection | BV9: Projection | BW9: Projection | BX9: Projection | BY9: Projection | BZ9: Projection | CA9: Projection | CB9: Projection | CC9: Projection | CD9: Projection | CE9: Projection | CF9: Projection | CG9: Projection | CH9: Projection | CI9: Projection | CJ9: Projection | CK9: Projection | CL9: Projection | CM9: Projection | CN9: Projection | CO9: Projection | CP9: Projection | CQ9: Projection | CR9: Projection | CS9: Projection | CT9: Projection | CU9: Projection | CV9: Projection | CW9: Projection | CX9: Projection | CY9: Projection | CZ9: Projection | DA9: Projection | DB9: Projection | DC9: Projection | DD9: Projection | DE9: Projection | DF9: Projection | DG9: Projection | DH9: Projection | DJ9: Actual | DK9: Actual | DL9: Actual | DM9: Budget | DN9: Projection | DO9: Projection | DP9: Projection | DQ9: Projection
B11: Revenue | DJ11: Growth Analysis
B12: Licensing | F12: =+'Revenue_Calcs'!F122 | G12: =+'Revenue_Calcs'!G122 | H12: =+'Revenue_Calcs'!H122 | I12: =+'Revenue_Calcs'!I122 | J12: =+'Revenue_Calcs'!J122 | K12: =+'Revenue_Calcs'!K122 | L12: =+'Revenue_Calcs'!L122 | M12: =+'Revenue_Calcs'!M122 | O12: =I12+992.899 | DK12: =+IFERROR(G12/F12-1,0) | DL12: =+IFERROR(H12/G12-1,0) | DM12: =+IFERROR(I12/H12-1,0) | DN12: =+IFERROR(J12/I12-1,0) | DP12: =+IFERROR(L12/K12-1,0) | DQ12: =+IFERROR(M12/L12-1,0)
B13: Managed Services | F13: =+'Revenue_Calcs'!F209 | G13: =+'Revenue_Calcs'!G209 | H13: =+'Revenue_Calcs'!H209 | I13: =+'Revenue_Calcs'!I209 | J13: =+'Revenue_Calcs'!J209 | K13: =+'Revenue_Calcs'!K209 | L13: =+'Revenue_Calcs'!L209 | M13: =+'Revenue_Calcs'!M209 | O13: =+I13 | DK13: =+IFERROR(G13/F13-1,0) | DL13: =+IFERROR(H13/G13-1,0) | DM13: =+IFERROR(I13/H13-1,0) | DN13: =+IFERROR(J13/I13-1,0) | DP13: =+IFERROR(L13/K13-1,0) | DQ13: =+IFERROR(M13/L13-1,0)
B14: Implementation | F14: =+'Revenue_Calcs'!F283 | G14: =+'Revenue_Calcs'!G283 | H14: =+'Revenue_Calcs'!H283 | I14: =+'Revenue_Calcs'!I283 | J14: =+'Revenue_Calcs'!J283 | K14: =+'Revenue_Calcs'!K283 | L14: =+'Revenue_Calcs'!L283 | M14: =+'Revenue_Calcs'!M283 | O14: =+I14 | DK14: =+IFERROR(G14/F14-1,0) | DL14: =+IFERROR(H14/G14-1,0) | DM14: =+IFERROR(I14/H14-1,0) | DN14: =+IFERROR(J14/I14-1,0) | DP14: =+IFERROR(L14/K14-1,0) | DQ14: =+IFERROR(M14/L14-1,0)
B15: Other Revenue | F15: =+'Revenue_Calcs'!F287 | G15: =+'Revenue_Calcs'!G287 | H15: =+'Revenue_Calcs'!H287 | I15: =+'Revenue_Calcs'!I287 | J15: =+'Revenue_Calcs'!J287 | K15: =+'Revenue_Calcs'!K287 | L15: =+'Revenue_Calcs'!L287 | M15: =+'Revenue_Calcs'!M287 | O15: =+I15 | DK15: =+IFERROR(G15/F15-1,0) | DL15: =+IFERROR(H15/G15-1,0) | DM15: =+IFERROR(I15/H15-1,0) | DN15: =+IFERROR(J15/I15-1,0) | DP15: =+IFERROR(L15/K15-1,0) | DQ15: =+IFERROR(M15/L15-1,0)
B16: Total Revenue | F16: =SUM(F12:F15) | G16: =SUM(G12:G15) | H16: =SUM(H12:H15) | I16: =SUM(I12:I15) | J16: =SUM(J12:J15) | K16: =SUM(K12:K15) | L16: =SUM(L12:L15) | M16: =SUM(M12:M15) | O16: =SUM(O12:O15) | DK16: =+G16/F16-1 | DL16: =+H16/G16-1 | DM16: =+I16/H16-1 | DN16: =+J16/I16-1 | DP16: =+L16/K16-1 | DQ16: =+M16/L16-1
B18: Cost of Sales | DJ18: Margin Analysis
B19: Licensing | F19: =+'COGS_Calcs'!F107 | G19: =+'COGS_Calcs'!G107 | H19: =+'COGS_Calcs'!H107 | I19: =+'COGS_Calcs'!I107 | J19: =+'COGS_Calcs'!J107 | K19: =+'COGS_Calcs'!K107 | L19: =+'COGS_Calcs'!L107 | M19: =+'COGS_Calcs'!M107 | O19: =+I19+((O12-I12)*0.11) | DJ19: =+F19/F$16 | DK19: =+G19/G$16 | DL19: =+H19/H$16 | DM19: =+I19/I$16 | DN19: =+J19/J$16 | DP19: =+L19/L$16 | DQ19: =+M19/M$16
B20: Managed Services | F20: =+'COGS_Calcs'!F159 | G20: =+'COGS_Calcs'!G159 | H20: =+'COGS_Calcs'!H159 | I20: =+'COGS_Calcs'!I159 | J20: =+'COGS_Calcs'!J159 | K20: =+'COGS_Calcs'!K159 | L20: =+'COGS_Calcs'!L159 | M20: =+'COGS_Calcs'!M159 | O20: =+I20 | DJ20: =+F20/F$16 | DK20: =+G20/G$16 | DL20: =+H20/H$16 | DM20: =+I20/I$16 | DN20: =+J20/J$16 | DP20: =+L20/L$16 | DQ20: =+M20/M$16
B21: Implementation | F21: =+'COGS_Calcs'!F173 | G21: =+'COGS_Calcs'!G173 | H21: =+'COGS_Calcs'!H173 | I21: =+'COGS_Calcs'!I173 | J21: =+'COGS_Calcs'!J173 | K21: =+'COGS_Calcs'!K173 | L21: =+'COGS_Calcs'!L173 | M21: =+'COGS_Calcs'!M173 | O21: =+I21 | DJ21: =+F21/F$16 | DK21: =+G21/G$16 | DL21: =+H21/H$16 | DM21: =+I21/I$16 | DN21: =+J21/J$16 | DP21: =+L21/L$16 | DQ21: =+M21/M$16
B22: Total Cost of Sales | F22: =SUM(F19:F21) | G22: =SUM(G19:G21) | H22: =SUM(H19:H21) | I22: =SUM(I19:I21) | J22: =SUM(J19:J21) | K22: =SUM(K19:K21) | L22: =SUM(L19:L21) | M22: =SUM(M19:M21) | O22: =SUM(O19:O21) | DJ22: =+F22/F$16 | DK22: =+G22/G$16 | DL22: =+H22/H$16 | DM22: =+I22/I$16 | DN22: =+J22/J$16 | DP22: =+L22/L$16 | DQ22: =+M22/M$16
B24: Gross Profit | F24: =+SUM(F16,-F22) | G24: =+SUM(G16,-G22) | H24: =+SUM(H16,-H22) | I24: =+SUM(I16,-I22) | J24: =+SUM(J16,-J22) | K24: =+SUM(K16,-K22) | L24: =+SUM(L16,-L22) | M24: =+SUM(M16,-M22) | O24: =+SUM(O16,-O22) | DJ24: =+F24/F$16 | DK24: =+G24/G$16 | DL24: =+H24/H$16 | DM24: =+I24/I$16 | DN24: =+J24/J$16 | DP24: =+L24/L$16 | DQ24: =+M24/M$16
B26: Operating Expenses
B27: Payroll & Benefits | F27: =+'Opex_Calcs'!F44 | G27: =+'Opex_Calcs'!G44 | H27: =+'Opex_Calcs'!H44 | I27: =+'Opex_Calcs'!I44 | J27: =+'Opex_Calcs'!J44 | K27: =+'Opex_Calcs'!K44 | L27: =+'Opex_Calcs'!L44 | M27: =+'Opex_Calcs'!M44 | O27: =+I27 | DJ27: =+F27/F$16 | DK27: =+G27/G$16 | DL27: =+H27/H$16 | DM27: =+I27/I$16 | DN27: =+J27/J$16 | DP27: =+L27/L$16 | DQ27: =+M27/M$16
B28: Office and Occupancy | F28: =+'Opex_Calcs'!F46 | G28: =+'Opex_Calcs'!G46 | H28: =+'Opex_Calcs'!H46 | I28: =+'Opex_Calcs'!I46 | J28: =+'Opex_Calcs'!J46 | K28: =+'Opex_Calcs'!K46 | L28: =+'Opex_Calcs'!L46 | M28: =+'Opex_Calcs'!M46 | O28: =+I28 | DJ28: =+F28/F$16 | DK28: =+G28/G$16 | DL28: =+H28/H$16 | DM28: =+I28/I$16 | DN28: =+J28/J$16 | DP28: =+L28/L$16 | DQ28: =+M28/M$16
B29: HR Other | F29: =+'Opex_Calcs'!F47 | G29: =+'Opex_Calcs'!G47 | H29: =+'Opex_Calcs'!H47 | I29: =+'Opex_Calcs'!I47 | J29: =+'Opex_Calcs'!J47 | K29: =+'Opex_Calcs'!K47 | L29: =+'Opex_Calcs'!L47 | M29: =+'Opex_Calcs'!M47 | O29: =+I29 | DJ29: =+F29/F$16 | DK29: =+G29/G$16 | DL29: =+H29/H$16 | DM29: =+I29/I$16 | DN29: =+J29/J$16 | DP29: =+L29/L$16 | DQ29: =+M29/M$16
B30: Sales and Marketing | F30: =+'Opex_Calcs'!F48 | G30: =+'Opex_Calcs'!G48 | H30: =+'Opex_Calcs'!H48 | I30: =+'Opex_Calcs'!I48 | J30: =+'Opex_Calcs'!J48 | K30: =+'Opex_Calcs'!K48 | L30: =+'Opex_Calcs'!L48 | M30: =+'Opex_Calcs'!M48 | O30: =+I30 | DJ30: =+F30/F$16 | DK30: =+G30/G$16 | DL30: =+H30/H$16 | DM30: =+I30/I$16 | DN30: =+J30/J$16 | DP30: =+L30/L$16 | DQ30: =+M30/M$16
B31: Other G&A | F31: =+'Opex_Calcs'!F49 | G31: =+'Opex_Calcs'!G49 | H31: =+'Opex_Calcs'!H49 | I31: =+'Opex_Calcs'!I49 | J31: =+'Opex_Calcs'!J49 | K31: =+'Opex_Calcs'!K49 | L31: =+'Opex_Calcs'!L49 | M31: =+'Opex_Calcs'!M49 | O31: =+I31 | DJ31: =+F31/F$16 | DK31: =+G31/G$16 | DL31: =+H31/H$16 | DM31: =+I31/I$16 | DN31: =+J31/J$16 | DP31: =+L31/L$16 | DQ31: =+M31/M$16
B32: Professional Fees | F32: =+'Opex_Calcs'!F50 | G32: =+'Opex_Calcs'!G50 | H32: =+'Opex_Calcs'!H50 | I32: =+'Opex_Calcs'!I50 | J32: =+'Opex_Calcs'!J50 | K32: =+'Opex_Calcs'!K50 | L32: =+'Opex_Calcs'!L50 | M32: =+'Opex_Calcs'!M50 | O32: =+I32 | DJ32: =+F32/F$16 | DK32: =+G32/G$16 | DL32: =+H32/H$16 | DM32: =+I32/I$16 | DN32: =+J32/J$16 | DP32: =+L32/L$16 | DQ32: =+M32/M$16
B33: Service Costs | F33: =+'Opex_Calcs'!F51 | G33: =+'Opex_Calcs'!G51 | H33: =+'Opex_Calcs'!H51 | I33: =+'Opex_Calcs'!I51 | J33: =+'Opex_Calcs'!J51 | K33: =+'Opex_Calcs'!K51 | L33: =+'Opex_Calcs'!L51 | M33: =+'Opex_Calcs'!M51 | O33: =+I33 | DJ33: =+F33/F$16 | DK33: =+G33/G$16 | DL33: =+H33/H$16 | DM33: =+I33/I$16 | DN33: =+J33/J$16 | DP33: =+L33/L$16 | DQ33: =+M33/M$16
B34: Total Operating Expenses | F34: =+'Opex_Calcs'!F52 | G34: =+'Opex_Calcs'!G52 | H34: =+'Opex_Calcs'!H52 | I34: =+'Opex_Calcs'!I52 | J34: =+'Opex_Calcs'!J52 | K34: =+'Opex_Calcs'!K52 | L34: =+'Opex_Calcs'!L52 | M34: =+'Opex_Calcs'!M52 | O34: =+I34 | DJ34: =+F34/F$16 | DK34: =+G34/G$16 | DL34: =+H34/H$16 | DM34: =+I34/I$16 | DN34: =+J34/J$16 | DP34: =+L34/L$16 | DQ34: =+M34/M$16
B35: Other Income / Expenses | F35: =+'Opex_Calcs'!F55 | G35: =+'Opex_Calcs'!G55 | H35: =+'Opex_Calcs'!H55 | I35: =+'Opex_Calcs'!I55 | J35: =+'Opex_Calcs'!J55 | K35: =+'Opex_Calcs'!K55 | L35: =+'Opex_Calcs'!L55 | M35: =+'Opex_Calcs'!M55 | O35: =+I35 | DJ35: =+F35/F$16 | DK35: =+G35/G$16 | DL35: =+H35/H$16 | DM35: =+I35/I$16 | DN35: =+J35/J$16 | DP35: =+L35/L$16 | DQ35: =+M35/M$16
B37: Reported EBITDA | F37: =+SUM(F24,-F34,-F35) | G37: =+SUM(G24,-G34,-G35) | H37: =+SUM(H24,-H34,-H35) | I37: =+SUM(I24,-I34,-I35) | J37: =+SUM(J24,-J34,-J35) | K37: =+SUM(K24,-K34,-K35) | L37: =+SUM(L24,-L34,-L35) | M37: =+SUM(M24,-M34,-M35) | O37: =+SUM(O24,-O34,-O35) | DJ37: =+F37/F$16 | DK37: =+G37/G$16 | DL37: =+H37/H$16 | DM37: =+I37/I$16 | DN37: =+J37/J$16 | DP37: =+L37/L$16 | DQ37: =+M37/M$16
B39: Adjustments
B40: Non-cash Stock-based Compensation | F40: =SUMIFS($Q40:$DI40,$Q$7:$DI$7,F$7) | G40: =SUMIFS($Q40:$DI40,$Q$7:$DI$7,G$7) | H40: =SUMIFS($Q40:$DI40,$Q$7:$DI$7,H$7) | I40: =SUMIFS($Q40:$DI40,$Q$7:$DI$7,I$7) | J40: =SUMIFS($Q40:$DI40,$Q$7:$DI$7,J$7) | K40: =SUMIFS($Q40:$DI40,$Q$7:$DI$7,K$7) | L40: =SUMIFS($Q40:$DI40,$Q$7:$DI$7,L$7) | M40: =SUMIFS($Q40:$DI40,$Q$7:$DI$7,M$7) | O40: =+I40 | Q40: 20.833 | R40: 20.833 | S40: 20.833 | T40: 20.833 | U40: 20.833 | V40: 20.833 | W40: 20.833 | X40: 20.833 | Y40: 20.833 | Z40: 20.833 | AA40: 20.833 | AB40: -204.124 | AC40: 8.33333 | AD40: 8.33333 | AE40: 8.33333 | AF40: 8.33333 | AG40: 8.33333 | AH40: 8.33333 | AI40: 8.33333 | AJ40: 8.33333 | AK40: 8.33333 | AL40: 8.33333 | AM40: 8.33333 | AN40: -27.88063 | AO40: 2.08333 | AP40: 2.08333 | AQ40: 2.08333 | AR40: 2.08333 | AS40: 2.08333 | AT40: 2.08333 | AU40: 2.08333 | AV40: 2.08333 | AW40: 2.08333 | AX40: 2.08333 | AY40: 2.08333 | AZ40: 237.01437 | BA40: 0 | BB40: 0 | BC40: 0 | BD40: 0 | BE40: 0 | BF40: 0 | BG40: 0 | BH40: 0 | BI40: 0 | BJ40: 0 | BK40: 0 | BL40: 0 | BM40: 0 | BN40: 0 | BO40: 0 | BP40: 0 | BQ40: 0 | BR40: 0 | BS40: 0 | BT40: 0 | BU40: 0 | BV40: 0 | BW40: 0 | BX40: 0 | BY40: 0 | BZ40: 0 | CA40: 0 | CB40: 0 | CC40: 0 | CD40: 0 | CE40: 0 | CF40: 0 | CG40: 0 | CH40: 0 | CI40: 0 | CJ40: 0 | CK40: 0 | CL40: 0 | CM40: 0 | CN40: 0 | CO40: 0 | CP40: 0 | CQ40: 0 | CR40: 0 | CS40: 0 | CT40: 0 | CU40: 0 | CV40: 0 | CW40: 0 | CX40: 0 | CY40: 0 | CZ40: 0 | DA40: 0 | DB40: 0 | DC40: 0 | DD40: 0 | DE40: 0 | DF40: 0 | DG40: 0 | DH40: 0 | DJ40: =+F40/F$16 | DK40: =+G40/G$16 | DL40: =+H40/H$16 | DM40: =+I40/I$16 | DN40: =+J40/J$16 | DP40: =+L40/L$16 | DQ40: =+M40/M$16
B41: Other Miscellaneous Items | F41: =SUMIFS($Q41:$DI41,$Q$7:$DI$7,F$7) | G41: =SUMIFS($Q41:$DI41,$Q$7:$DI$7,G$7) | H41: =SUMIFS($Q41:$DI41,$Q$7:$DI$7,H$7) | I41: =SUMIFS($Q41:$DI41,$Q$7:$DI$7,I$7) | J41: =SUMIFS($Q41:$DI41,$Q$7:$DI$7,J$7) | K41: =SUMIFS($Q41:$DI41,$Q$7:$DI$7,K$7) | L41: =SUMIFS($Q41:$DI41,$Q$7:$DI$7,L$7) | M41: =SUMIFS($Q41:$DI41,$Q$7:$DI$7,M$7) | O41: =+I41 | Q41: 9.25165 | R41: 3.01295 | S41: 16.41295 | T41: -4.58705 | U41: 4.78698 | V41: 3.01295 | W41: 13.01295 | X41: 20.44512 | Y41: 17.51013 | Z41: 1.88017 | AA41: 11.52846 | AB41: 14.82482 | AC41: 12.5 | AD41: 13.65994 | AE41: 22.392 | AF41: 19.868 | AG41: 4.9663 | AH41: 18.383 | AI41: -69.84 | AJ41: 2.502 | AK41: 2.549 | AL41: 3.96917 | AM41: 3.8983 | AN41: 11.64995 | AO41: 0.76966667 | AP41: 0.76966667 | AQ41: 1.5246667 | AR41: 0.75466667 | AS41: 2.2554467 | AT41: -5.2453333 | AU41: -0.29328333 | AV41: 3.3546667 | AW41: 15.004667 | AX41: 14.5 | AY41: 1.38931 | AZ41: 0 | BA41: 0 | BB41: 0 | BC41: 0 | BD41: 0 | BE41: 0 | BF41: 0 | BG41: 0 | BH41: 0 | BI41: 0 | BJ41: 0 | BK41: 0 | BL41: 0 | BM41: 0 | BN41: 0 | BO41: 0 | BP41: 0 | BQ41: 0 | BR41: 0 | BS41: 0 | BT41: 0 | BU41: 0 | BV41: 0 | BW41: 0 | BX41: 0 | BY41: 0 | BZ41: 0 | CA41: 0 | CB41: 0 | CC41: 0 | CD41: 0 | CE41: 0 | CF41: 0 | CG41: 0 | CH41: 0 | CI41: 0 | CJ41: 0 | CK41: 0 | CL41: 0 | CM41: 0 | CN41: 0 | CO41: 0 | CP41: 0 | CQ41: 0 | CR41: 0 | CS41: 0 | CT41: 0 | CU41: 0 | CV41: 0 | CW41: 0 | CX41: 0 | CY41: 0 | CZ41: 0 | DA41: 0 | DB41: 0 | DC41: 0 | DD41: 0 | DE41: 0 | DF41: 0 | DG41: 0 | DH41: 0 | DJ41: =+F41/F$16 | DK41: =+G41/G$16 | DL41: =+H41/H$16 | DM41: =+I41/I$16 | DN41: =+J41/J$16 | DP41: =+L41/L$16 | DQ41: =+M41/M$16
B42: Employee Related Expenses | F42: =SUMIFS($Q42:$DI42,$Q$7:$DI$7,F$7) | G42: =SUMIFS($Q42:$DI42,$Q$7:$DI$7,G$7) | H42: =SUMIFS($Q42:$DI42,$Q$7:$DI$7,H$7) | I42: =SUMIFS($Q42:$DI42,$Q$7:$DI$7,I$7) | J42: =SUMIFS($Q42:$DI42,$Q$7:$DI$7,J$7) | K42: =SUMIFS($Q42:$DI42,$Q$7:$DI$7,K$7) | L42: =SUMIFS($Q42:$DI42,$Q$7:$DI$7,L$7) | M42: =SUMIFS($Q42:$DI42,$Q$7:$DI$7,M$7) | O42: =+I42 | Q42: 8.4869783 | R42: 38.358638 | S42: 8.3586383 | T42: 10.358638 | U42: 8.3586383 | V42: 8.3586383 | W42: 11.358638 | X42: 18.858638 | Y42: 17.358638 | Z42: 13.983638 | AA42: 19.014638 | AB42: -79.323362 | AC42: 13.517087 | AD42: 13.095877 | AE42: 18.054667 | AF42: 16.147717 | AG42: 3.7620867 | AH42: -1.2379133 | AI42: -1.2379133 | AJ42: -1.2379133 | AK42: -1.2379233 | AL42: -1.2379233 | AM42: 55.257077 | AN42: -9.0089233 | AO42: 8.04 | AP42: 0.52568 | AQ42: 0 | AR42: 0 | AS42: 0 | AT42: 0.28933 | AU42: 0 | AV42: 5 | AW42: 17.11879 | AX42: 0 | AY42: 0 | AZ42: 0 | BA42: 0 | BB42: 0 | BC42: 0 | BD42: 0 | BE42: 0 | BF42: 0 | BG42: 0 | BH42: 0 | BI42: 0 | BJ42: 0 | BK42: 0 | BL42: 0 | BM42: 0 | BN42: 0 | BO42: 0 | BP42: 0 | BQ42: 0 | BR42: 0 | BS42: 0 | BT42: 0 | BU42: 0 | BV42: 0 | BW42: 0 | BX42: 0 | BY42: 0 | BZ42: 0 | CA42: 0 | CB42: 0 | CC42: 0 | CD42: 0 | CE42: 0 | CF42: 0 | CG42: 0 | CH42: 0 | CI42: 0 | CJ42: 0 | CK42: 0 | CL42: 0 | CM42: 0 | CN42: 0 | CO42: 0 | CP42: 0 | CQ42: 0 | CR42: 0 | CS42: 0 | CT42: 0 | CU42: 0 | CV42: 0 | CW42: 0 | CX42: 0 | CY42: 0 | CZ42: 0 | DA42: 0 | DB42: 0 | DC42: 0 | DD42: 0 | DE42: 0 | DF42: 0 | DG42: 0 | DH42: 0 | DJ42: =+F42/F$16 | DK42: =+G42/G$16 | DL42: =+H42/H$16 | DM42: =+I42/I$16 | DN42: =+J42/J$16 | DP42: =+L42/L$16 | DQ42: =+M42/M$16
B43: Non-recurring Build Subsidies | F43: =SUMIFS($Q43:$DI43,$Q$7:$DI$7,F$7) | G43: =SUMIFS($Q43:$DI43,$Q$7:$DI$7,G$7) | H43: =SUMIFS($Q43:$DI43,$Q$7:$DI$7,H$7) | I43: =SUMIFS($Q43:$DI43,$Q$7:$DI$7,I$7) | J43: =SUMIFS($Q43:$DI43,$Q$7:$DI$7,J$7) | K43: =SUMIFS($Q43:$DI43,$Q$7:$DI$7,K$7) | L43: =SUMIFS($Q43:$DI43,$Q$7:$DI$7,L$7) | M43: =SUMIFS($Q43:$DI43,$Q$7:$DI$7,M$7) | O43: =+I43 | Q43: 135.84913 | R43: 219.74271 | S43: 294.61578 | T43: 237.61969 | U43: 282.9635 | V43: 333.30398 | W43: 341.19059 | X43: 405.02271 | Y43: 323.66688 | Z43: 428.12455 | AA43: 312.23943 | AB43: 277.35696 | AC43: 290.11101 | AD43: 288.41538 | AE43: 370.12266 | AF43: 315.70853 | AG43: 291.44613 | AH43: 213.13591 | AI43: 169.27227 | AJ43: 137.43883 | AK43: 120.37583 | AL43: 83.636543 | AM43: -6.8386667 | AN43: -3.91747 | AO43: 61.8405 | AP43: 37.405 | AQ43: 51.271 | AR43: 47.215 | AS43: 48.908 | AT43: -15.65 | AU43: -14.851 | AV43: 61.208 | AW43: -0.169 | AX43: 30.794 | AY43: 26.507 | AZ43: 23.922 | BA43: 12.1 | BB43: 13.695 | BC43: 52.25 | BD43: 34.241182 | BE43: 13.521848 | BF43: 24.521848 | BG43: 27.271848 | BH43: 39.741182 | BI43: 36.991182 | BJ43: 23.241182 | BK43: 19.721182 | BL43: 12.241182 | BM43: 13.441182 | BN43: 7.6411818 | BO43: 8.7 | BP43: 5.8 | BQ43: 2.9 | BR43: 0 | BS43: 0 | BT43: 0 | BU43: 0 | BV43: 0 | BW43: 0 | BX43: 0 | BY43: 0 | BZ43: 0 | CA43: 0 | CB43: 0 | CC43: 0 | CD43: 0 | CE43: 0 | CF43: 0 | CG43: 0 | CH43: 0 | CI43: 0 | CJ43: 0 | CK43: 0 | CL43: 0 | CM43: 0 | CN43: 0 | CO43: 0 | CP43: 0 | CQ43: 0 | CR43: 0 | CS43: 0 | CT43: 0 | CU43: 0 | CV43: 0 | CW43: 0 | CX43: 0 | CY43: 0 | CZ43: 0 | DA43: 0 | DB43: 0 | DC43: 0 | DD43: 0 | DE43: 0 | DF43: 0 | DG43: 0 | DH43: 0 | DJ43: =+F43/F$16 | DK43: =+G43/G$16 | DL43: =+H43/H$16 | DM43: =+I43/I$16 | DN43: =+J43/J$16 | DP43: =+L43/L$16 | DQ43: =+M43/M$16
B44: Duplicative Hosting Costs | F44: =SUMIFS($Q44:$DI44,$Q$7:$DI$7,F$7) | G44: =SUMIFS($Q44:$DI44,$Q$7:$DI$7,G$7) | H44: =SUMIFS($Q44:$DI44,$Q$7:$DI$7,H$7) | I44: =SUMIFS($Q44:$DI44,$Q$7:$DI$7,I$7) | J44: =SUMIFS($Q44:$DI44,$Q$7:$DI$7,J$7) | K44: =SUMIFS($Q44:$DI44,$Q$7:$DI$7,K$7) | L44: =SUMIFS($Q44:$DI44,$Q$7:$DI$7,L$7) | M44: =SUMIFS($Q44:$DI44,$Q$7:$DI$7,M$7) | O44: =+I44 | Q44: 0 | R44: 0 | S44: 0 | T44: 0 | U44: 0 | V44: 0 | W44: 0 | X44: 0 | Y44: 0 | Z44: 0 | AA44: 0 | AB44: 0 | AC44: 0 | AD44: 0 | AE44: 3.51225 | AF44: 3.51225 | AG44: 3.51225 | AH44: 29.2315 | AI44: 1.6034413 | AJ44: 1.6034413 | AK44: 3.9133879 | AL44: 5.2761676 | AM44: 5.1352645 | AN44: 7.4517559 | AO44: 14.374712 | AP44: 11.373587 | AQ44: 23.293 | AR44: 22.4 | AS44: 9.028 | AT44: 6.87705 | AU44: 6.44708 | AV44: 6.44708 | AW44: 6.44708 | AX44: 6.44708 | AY44: 6.44708 | AZ44: 6.44708 | BA44: 0 | BB44: 0 | BC44: 0 | BD44: 0 | BE44: 0 | BF44: 0 | BG44: 0 | BH44: 0 | BI44: 0 | BJ44: 0 | BK44: 0 | BL44: 0 | BM44: 0 | BN44: 0 | BO44: 0 | BP44: 0 | BQ44: 0 | BR44: 0 | BS44: 0 | BT44: 0 | BU44: 0 | BV44: 0 | BW44: 0 | BX44: 0 | BY44: 0 | BZ44: 0 | CA44: 0 | CB44: 0 | CC44: 0 | CD44: 0 | CE44: 0 | CF44: 0 | CG44: 0 | CH44: 0 | CI44: 0 | CJ44: 0 | CK44: 0 | CL44: 0 | CM44: 0 | CN44: 0 | CO44: 0 | CP44: 0 | CQ44: 0 | CR44: 0 | CS44: 0 | CT44: 0 | CU44: 0 | CV44: 0 | CW44: 0 | CX44: 0 | CY44: 0 | CZ44: 0 | DA44: 0 | DB44: 0 | DC44: 0 | DD44: 0 | DE44: 0 | DF44: 0 | DG44: 0 | DH44: 0 | DJ44: =+F44/F$16 | DK44: =+G44/G$16 | DL44: =+H44/H$16 | DM44: =+I44/I$16 | DN44: =+J44/J$16 | DP44: =+L44/L$16 | DQ44: =+M44/M$16
B45: COVID-19 Marketing Cost Savings | F45: =SUMIFS($Q45:$DI45,$Q$7:$DI$7,F$7) | G45: =SUMIFS($Q45:$DI45,$Q$7:$DI$7,G$7) | H45: =SUMIFS($Q45:$DI45,$Q$7:$DI$7,H$7) | I45: =SUMIFS($Q45:$DI45,$Q$7:$DI$7,I$7) | J45: =SUMIFS($Q45:$DI45,$Q$7:$DI$7,J$7) | K45: =SUMIFS($Q45:$DI45,$Q$7:$DI$7,K$7) | L45: =SUMIFS($Q45:$DI45,$Q$7:$DI$7,L$7) | M45: =SUMIFS($Q45:$DI45,$Q$7:$DI$7,M$7) | O45: =+I45 | Q45: 0 | R45: 0 | S45: 0 | T45: 0 | U45: 0 | V45: 0 | W45: 0 | X45: 0 | Y45: 147.40685 | Z45: 63.98637 | AA45: 0 | AB45: 0 | AC45: 0 | AD45: 0 | AE45: 0 | AF45: 0 | AG45: 0 | AH45: 0 | AI45: 0 | AJ45: 0 | AK45: 0 | AL45: 0 | AM45: 0 | AN45: 0 | AO45: 0 | AP45: 0 | AQ45: 11.452 | AR45: 0 | AS45: 0 | AT45: 0 | AU45: 0 | AV45: 0 | AW45: 0 | AX45: 0 | AY45: 0 | AZ45: 0 | BA45: 0 | BB45: 0 | BC45: 0 | BD45: 0 | BE45: 0 | BF45: 0 | BG45: 0 | BH45: 0 | BI45: 0 | BJ45: 0 | BK45: 0 | BL45: 0 | BM45: 0 | BN45: 0 | BO45: 0 | BP45: 0 | BQ45: 0 | BR45: 0 | BS45: 0 | BT45: 0 | BU45: 0 | BV45: 0 | BW45: 0 | BX45: 0 | BY45: 0 | BZ45: 0 | CA45: 0 | CB45: 0 | CC45: 0 | CD45: 0 | CE45: 0 | CF45: 0 | CG45: 0 | CH45: 0 | CI45: 0 | CJ45: 0 | CK45: 0 | CL45: 0 | CM45: 0 | CN45: 0 | CO45: 0 | CP45: 0 | CQ45: 0 | CR45: 0 | CS45: 0 | CT45: 0 | CU45: 0 | CV45: 0 | CW45: 0 | CX45: 0 | CY45: 0 | CZ45: 0 | DA45: 0 | DB45: 0 | DC45: 0 | DD45: 0 | DE45: 0 | DF45: 0 | DG45: 0 | DH45: 0 | DJ45: =+F45/F$16 | DK45: =+G45/G$16 | DL45: =+H45/H$16 | DM45: =+I45/I$16 | DN45: =+J45/J$16 | DP45: =+L45/L$16 | DQ45: =+M45/M$16
B46: Normalized Legal Fees | F46: =SUMIFS($Q46:$DI46,$Q$7:$DI$7,F$7) | G46: =SUMIFS($Q46:$DI46,$Q$7:$DI$7,G$7) | H46: =SUMIFS($Q46:$DI46,$Q$7:$DI$7,H$7) | I46: =SUMIFS($Q46:$DI46,$Q$7:$DI$7,I$7) | J46: =SUMIFS($Q46:$DI46,$Q$7:$DI$7,J$7) | K46: =SUMIFS($Q46:$DI46,$Q$7:$DI$7,K$7) | L46: =SUMIFS($Q46:$DI46,$Q$7:$DI$7,L$7) | M46: =SUMIFS($Q46:$DI46,$Q$7:$DI$7,M$7) | O46: =+I46 | Q46: 14.423127 | R46: 14.423127 | S46: 39.423127 | T46: 17.423127 | U46: 17.423127 | V46: -2.5768733 | W46: -2.5768733 | X46: -40.012373 | Y46: 4.0137367 | Z46: -2.7363733 | AA46: -1.4603733 | AB46: -7.2245233 | AC46: 18.256457 | AD46: 18.256457 | AE46: 16.441457 | AF46: 8.2929467 | AG46: 16.230577 | AH46: 13.560577 | AI46: 16.230577 | AJ46: 15.223577 | AK46: 11.818587 | AL46: -128.77147 | AM46: -2.2628733 | AN46: -2.5768733 | AO46: 0 | AP46: 0 | AQ46: 0 | AR46: 0 | AS46: 0 | AT46: 0 | AU46: 0 | AV46: 0 | AW46: 0 | AX46: 0 | AY46: 0 | AZ46: 0 | BA46: 0 | BB46: 0 | BC46: 0 | BD46: 0 | BE46: 0 | BF46: 0 | BG46: 0 | BH46: 0 | BI46: 0 | BJ46: 0 | BK46: 0 | BL46: 0 | BM46: 0 | BN46: 0 | BO46: 0 | BP46: 0 | BQ46: 0 | BR46: 0 | BS46: 0 | BT46: 0 | BU46: 0 | BV46: 0 | BW46: 0 | BX46: 0 | BY46: 0 | BZ46: 0 | CA46: 0 | CB46: 0 | CC46: 0 | CD46: 0 | CE46: 0 | CF46: 0 | CG46: 0 | CH46: 0 | CI46: 0 | CJ46: 0 | CK46: 0 | CL46: 0 | CM46: 0 | CN46: 0 | CO46: 0 | CP46: 0 | CQ46: 0 | CR46: 0 | CS46: 0 | CT46: 0 | CU46: 0 | CV46: 0 | CW46: 0 | CX46: 0 | CY46: 0 | CZ46: 0 | DA46: 0 | DB46: 0 | DC46: 0 | DD46: 0 | DE46: 0 | DF46: 0 | DG46: 0 | DH46: 0 | DJ46: =+F46/F$16 | DK46: =+G46/G$16 | DL46: =+H46/H$16 | DM46: =+I46/I$16 | DN46: =+J46/J$16 | DP46: =+L46/L$16 | DQ46: =+M46/M$16
B47: Eligible Costs for Capitalization | F47: =SUMIFS($Q47:$DI47,$Q$7:$DI$7,F$7) | G47: =SUMIFS($Q47:$DI47,$Q$7:$DI$7,G$7) | H47: =SUMIFS($Q47:$DI47,$Q$7:$DI$7,H$7) | I47: =SUMIFS($Q47:$DI47,$Q$7:$DI$7,I$7) | J47: =SUMIFS($Q47:$DI47,$Q$7:$DI$7,J$7) | K47: =SUMIFS($Q47:$DI47,$Q$7:$DI$7,K$7) | L47: =SUMIFS($Q47:$DI47,$Q$7:$DI$7,L$7) | M47: =SUMIFS($Q47:$DI47,$Q$7:$DI$7,M$7) | O47: =+I47 | DJ47: =+F47/F$16 | DK47: =+G47/G$16 | DL47: =+H47/H$16 | DM47: =+I47/I$16 | DN47: =+J47/J$16 | DP47: =+L47/L$16 | DQ47: =+M47/M$16
B48: Total Adjustments | F48: =SUM(F40:F47) | G48: =SUM(G40:G47) | H48: =SUM(H40:H47) | I48: =SUM(I40:I47) | J48: =SUM(J40:J47) | K48: =SUM(K40:K47) | L48: =SUM(L40:L47) | M48: =SUM(M40:M47) | O48: =+I48 | Q48: =SUM(Q40:Q46) | DJ48: =+F48/F$16 | DK48: =+G48/G$16 | DL48: =+H48/H$16 | DM48: =+I48/I$16 | DN48: =+J48/J$16 | DP48: =+L48/L$16 | DQ48: =+M48/M$16
...

Sheet Calculations ->

Sheet Revenue_Calcs
B2: Project Shasta
B3: {=MID(CELL("filename",A1),FIND("]",CELL("filename",A1))+1,255)}
B4: Spring 2022
B5: CONFIDENTIAL
E7: 2018 | F7: =+E7+1 | G7: =+F7+1 | H7: =+G7+1 | I7: =+H7+1 | J7: =+I7+1 | K7: =+J7+1 | L7: =+K7+1 | M7: =+L7+1 | O7: =+YEAR(O8) | P7: =+YEAR(P8) | Q7: =+YEAR(Q8) | R7: =+YEAR(R8) | S7: =+YEAR(S8) | T7: =+YEAR(T8) | U7: =+YEAR(U8) | V7: =+YEAR(V8) | ... DR7: =+YEAR(DR8)
E8: =+DATE(E7,12,31) | F8: =+DATE(F7,12,31) | G8: =+DATE(G7,12,31) | H8: =+DATE(H7,12,31) | I8: =+DATE(I7,12,31) | J8: =+DATE(J7,12,31) | K8: =+DATE(K7,12,31) | L8: =+DATE(L7,12,31) | M8: =+DATE(M7,12,31) | O8: 43131 | P8: =+EOMONTH(O8,1) | Q8: =+EOMONTH(P8,1) | R8: =+EOMONTH(Q8,1) | S8: =+EOMONTH(R8,1) | T8: =+EOMONTH(S8,1) | U8: =+EOMONTH(T8,1) | V8: =+EOMONTH(U8,1) | W8: =+EOMONTH(V8,1) | ... DR8: =+EOMONTH(DQ8,1) | DT8: Upsell / Downsell
B9: $ in thousands | E9: Actual | F9: Actual | G9: Actual | H9: Actual | I9: Budget | J9: Projection | K9: Projection | L9: Projection | M9: Projection | O9: Actual | P9: Actual | Q9: Actual | R9: Actual | S9: Actual | T9: Actual | U9: Actual | V9: Actual | W9: Actual | X9: Actual | Y9: Actual | Z9: Actual | AA9: Actual | AB9: Actual | AC9: Actual | AD9: Actual | AE9: Actual | AF9: Actual | AG9: Actual | AH9: Actual | AI9: Actual | AJ9: Actual | AK9: Actual | AL9: Actual | AM9: Actual | AN9: Actual | AO9: Actual | AP9: Actual | AQ9: Actual | AR9: Actual | AS9: Actual | AT9: Actual | AU9: Actual | AV9: Actual | AW9: Actual | AX9: Actual | AY9: Actual | AZ9: Actual | BA9: Actual | BB9: Actual | BC9: Actual | BD9: Actual | BE9: Actual | BF9: Actual | BG9: Actual | BH9: Actual | BI9: Actual | BJ9: Actual | BK9: Actual | BL9: Actual | BM9: Actual | BN9: Projection | BO9: Projection | BP9: Projection | BQ9: Projection | BR9: Projection | BS9: Projection | BT9: Projection | BU9: Projection | BV9: Projection | BW9: Projection | BX9: Projection | BY9: Projection | BZ9: Projection | CA9: Projection | CB9: Projection | CC9: Projection | CD9: Projection | CE9: Projection | CF9: Projection | CG9: Projection | CH9: Projection | CI9: Projection | CJ9: Projection | CK9: Projection | CL9: Projection | CM9: Projection | CN9: Projection | CO9: Projection | CP9: Projection | CQ9: Projection | CR9: Projection | CS9: Projection | CT9: Projection | CU9: Projection | CV9: Projection | CW9: Projection | CX9: Projection | CY9: Projection | CZ9: Projection | DA9: Projection | DB9: Projection | DC9: Projection | DD9: Projection | DE9: Projection | DF9: Projection | DG9: Projection | DH9: Projection | DI9: Projection | DJ9: Projection | DK9: Projection | DL9: Projection | DM9: Projection | DN9: Projection | DO9: Projection | DP9: Projection | DQ9: Projection | DR9: Projection | DT9: 2019 | DU9: 2020 | DV9: 2021 | DW9: 2022
B11: Licensing
B13: AACN | C13: Lower Middle Market | E13: =+SUMIFS($O13:$DR13,$O$7:$DR$7,E$7) | F13: =+SUMIFS($O13:$DR13,$O$7:$DR$7,F$7) | G13: =+SUMIFS($O13:$DR13,$O$7:$DR$7,G$7) | H13: =+SUMIFS($O13:$DR13,$O$7:$DR$7,H$7) | I13: =+SUMIFS($O13:$DR13,$O$7:$DR$7,I$7) | J13: =+SUMIFS($O13:$DR13,$O$7:$DR$7,J$7) | K13: =+SUMIFS($O13:$DR13,$O$7:$DR$7,K$7) | L13: =+SUMIFS($O13:$DR13,$O$7:$DR$7,L$7) | M13: =+SUMIFS($O13:$DR13,$O$7:$DR$7,M$7) | O13: 0 | P13: 0 | Q13: 0 | R13: 0 | S13: 0 | T13: 0 | U13: 0 | V13: 0 | W13: 0 | X13: 0 | Y13: 0 | Z13: 0 | AA13: 0 | AB13: 0 | AC13: 0 | AD13: 0 | AE13: 0 | AF13: 0 | AG13: 0 | AH13: 0 | AI13: 0 | AJ13: 0 | AK13: 0 | AL13: 13.416 | AM13: 9.584 | AN13: 9.583 | AO13: 9.583 | AP13: 9.583 | AQ13: 9.583 | AR13: 9.584 | AS13: 9.584 | AT13: 9.584 | AU13: 8.23 | AV13: 9.583 | AW13: 9.584 | AX13: 9.871 | AY13: 9.8708333 | AZ13: 9.8708333 | BA13: 9.8708333 | BB13: 9.8708333 | BC13: 9.8708333 | BD13: 9.8708333 | BE13: 9.8708333 | BF13: 9.8708333 | BG13: 9.8708333 | BH13: 9.8708333 | BI13: 9.8708333 | BJ13: 10.166958 | BK13: 10.166958 | BL13: 10.166958 | BM13: 10.166958 | BN13: 10.166958 | BO13: 10.166958 | BP13: 10.166958 | BQ13: 10.166958 | BR13: 10.166958 | BS13: 10.166958 | BT13: 10.166958 | BU13: 10.166958 | BV13: 10.471967 | BW13: 10.471967 | BX13: 10.471967 | BY13: 10.471967 | BZ13: 10.471967 | CA13: 10.471967 | CB13: 10.471967 | CC13: 10.471967 | CD13: 10.471967 | CE13: 10.471967 | CF13: 10.471967 | CG13: 10.471967 | CH13: 10.786126 | CI13: 10.786126 | CJ13: 10.786126 | CK13: 10.786126 | CL13: 10.786126 | CM13: 10.786126 | CN13: 10.786126 | CO13: 10.786126 | CP13: 10.786126 | CQ13: 10.786126 | CR13: 10.786126 | CS13: 10.786126 | CT13: 0 | CU13: 0 | CV13: 0 | CW13: 0 | CX13: 0 | CY13: 0 | CZ13: 0 | DA13: 0 | DB13: 0 | DC13: 0 | DD13: 0 | DE13: 0 | DF13: 0 | DG13: 0 | DH13: 0 | DI13: 0 | DJ13: 0 | DK13: 0 | DL13: 0 | DM13: 0 | DN13: 0 | DO13: 0 | DP13: 0 | DQ13: 0 | DR13: 0 | DT13: =+F13-E13 | DU13: =+G13-F13 | DV13: =+H13-G13 | DW13: =+I13-H13
B14: AACR | C14: Lower Middle Market | E14: =+SUMIFS($O14:$DR14,$O$7:$DR$7,E$7) | F14: =+SUMIFS($O14:$DR14,$O$7:$DR$7,F$7) | G14: =+SUMIFS($O14:$DR14,$O$7:$DR$7,G$7) | H14: =+SUMIFS($O14:$DR14,$O$7:$DR$7,H$7) | I14: =+SUMIFS($O14:$DR14,$O$7:$DR$7,I$7) | J14: =+SUMIFS($O14:$DR14,$O$7:$DR$7,J$7) | K14: =+SUMIFS($O14:$DR14,$O$7:$DR$7,K$7) | L14: =+SUMIFS($O14:$DR14,$O$7:$DR$7,L$7) | M14: =+SUMIFS($O14:$DR14,$O$7:$DR$7,M$7) | O14: 0 | P14: 0 | Q14: 0 | R14: 0 | S14: 0 | T14: 0 | U14: 0 | V14: 0 | W14: 0 | X14: 0 | Y14: 0 | Z14: 0 | AA14: 0 | AB14: 0 | AC14: 0 | AD14: 0 | AE14: 0 | AF14: 0 | AG14: 0 | AH14: 0 | AI14: 0 | AJ14: 0 | AK14: 0 | AL14: 0 | AM14: 0 | AN14: 0 | AO14: 0 | AP14: 0 | AQ14: 0 | AR14: 0 | AS14: 0 | AT14: 0 | AU14: 0 | AV14: 0 | AW14: 0 | AX14: 0 | AY14: 0 | AZ14: 0 | BA14: 0 | BB14: 0 | BC14: 0 | BD14: 0 | BE14: 0 | BF14: 0 | BG14: 0 | BH14: 2.916 | BI14: 2.916 | BJ14: 14.583 | BK14: 14.583333 | BL14: 14.583333 | BM14: 14.583333 | BN14: 14.583333 | BO14: 14.583333 | BP14: 14.583333 | BQ14: 14.583333 | BR14: 14.583333 | BS14: 14.583333 | BT14: 14.583333 | BU14: 14.583333 | BV14: 15.3125 | BW14: 15.3125 | BX14: 15.3125 | BY14: 15.3125 | BZ14: 15.3125 | CA14: 15.3125 | CB14: 15.3125 | CC14: 15.3125 | CD14: 15.3125 | CE14: 15.3125 | CF14: 15.3125 | CG14: 15.3125 | CH14: 16.078 | CI14: 16.078 | CJ14: 16.078 | CK14: 16.078 | CL14: 16.078 | CM14: 16.078 | CN14: 16.078 | CO14: 16.078 | CP14: 16.078 | CQ14: 16.078 | CR14: 16.078 | CS14: 16.078 | CT14: 16.882 | CU14: 16.882 | CV14: 16.882 | CW14: 16.882 | CX14: 16.882 | CY14: 16.882 | CZ14: 16.882 | DA14: 16.882 | DB14: 16.882 | DC14: 16.882 | DD14: 16.882 | DE14: 16.882 | DF14: 17.7261 | DG14: 17.7261 | DH14: 17.7261 | DI14: 17.7261 | DJ14: 17.7261 | DK14: 17.7261 | DL14: 17.7261 | DM14: 17.7261 | DN14: 17.7261 | DO14: 17.7261 | DP14: 17.7261 | DQ14: 17.7261 | DR14: 0 | DT14: =+F14-E14 | DU14: =+G14-F14 | DV14: =+H14-G14 | DW14: =+I14-H14
B15: AAI | C15: Lower Middle Market | E15: =+SUMIFS($O15:$DR15,$O$7:$DR$7,E$7) | F15: =+SUMIFS($O15:$DR15,$O$7:$DR$7,F$7) | G15: =+SUMIFS($O15:$DR15,$O$7:$DR$7,G$7) | H15: =+SUMIFS($O15:$DR15,$O$7:$DR$7,H$7) | I15: =+SUMIFS($O15:$DR15,$O$7:$DR$7,I$7) | J15: =+SUMIFS($O15:$DR15,$O$7:$DR$7,J$7) | K15: =+SUMIFS($O15:$DR15,$O$7:$DR$7,K$7) | L15: =+SUMIFS($O15:$DR15,$O$7:$DR$7,L$7) | M15: =+SUMIFS($O15:$DR15,$O$7:$DR$7,M$7) | O15: 0 | P15: 0 | Q15: 0 | R15: 0 | S15: 0 | T15: 0 | U15: 0 | V15: 0 | W15: 0 | X15: 0 | Y15: 0 | Z15: 0 | AA15: 0 | AB15: 0 | AC15: 0 | AD15: 0 | AE15: 0 | AF15: 0 | AG15: 0 | AH15: 0 | AI15: 0 | AJ15: 0 | AK15: 0 | AL15: 0 | AM15: 0 | AN15: 0 | AO15: 0 | AP15: 0 | AQ15: 0 | AR15: 0 | AS15: 0 | AT15: 0 | AU15: 0 | AV15: 0 | AW15: 0 | AX15: 0 | AY15: 0 | AZ15: 0 | BA15: 0 | BB15: 0 | BC15: 0 | BD15: 0 | BE15: 0 | BF15: 0 | BG15: 0 | BH15: 0 | BI15: 0 | BJ15: 0 | BK15: 0 | BL15: 0 | BM15: 2 | BN15: 2 | BO15: 2 | BP15: 2 | BQ15: 2 | BR15: 2 | BS15: 2 | BT15: 2 | BU15: 12.458333 | BV15: 12.458333 | BW15: 12.458333 | BX15: 12.458333 | BY15: 12.458333 | BZ15: 12.458333 | CA15: 12.458333 | CB15: 12.458333 | CC15: 12.458333 | CD15: 12.458333 | CE15: 12.458333 | CF15: 12.458333 | CG15: 12.832083 | CH15: 12.832083 | CI15: 12.832083 | CJ15: 12.832083 | CK15: 12.832083 | CL15: 12.832083 | CM15: 12.832083 | CN15: 12.832083 | CO15: 12.832083 | CP15: 12.832083 | CQ15: 12.832083 | CR15: 12.832083 | CS15: 13.217046 | CT15: 13.217046 | CU15: 13.217046 | CV15: 13.217046 | CW15: 13.217046 | CX15: 13.217046 | CY15: 13.217046 | CZ15: 13.217046 | DA15: 13.217046 | DB15: 13.217046 | DC15: 13.217046 | DD15: 13.217046 | DE15: 13.613557 | DF15: 13.613557 | DG15: 13.613557 | DH15: 13.613557 | DI15: 13.613557 | DJ15: 13.613557 | DK15: 13.613557 | DL15: 13.613557 | DM15: 13.613557 | DN15: 13.613557 | DO15: 13.613557 | DP15: 13.613557 | DQ15: 14.021964 | DR15: 14.021964 | DT15: =+F15-E15 | DU15: =+G15-F15 | DV15: =+H15-G15 | DW15: =+I15-H15
B16: AAOS | C16: Upper Middle Market | E16: =+SUMIFS($O16:$DR16,$O$7:$DR$7,E$7) | F16: =+SUMIFS($O16:$DR16,$O$7:$DR$7,F$7) | G16: =+SUMIFS($O16:$DR16,$O$7:$DR$7,G$7) | H16: =+SUMIFS($O16:$DR16,$O$7:$DR$7,H$7) | I16: =+SUMIFS($O16:$DR16,$O$7:$DR$7,I$7) | J16: =+SUMIFS($O16:$DR16,$O$7:$DR$7,J$7) | K16: =+SUMIFS($O16:$DR16,$O$7:$DR$7,K$7) | L16: =+SUMIFS($O16:$DR16,$O$7:$DR$7,L$7) | M16: =+SUMIFS($O16:$DR16,$O$7:$DR$7,M$7) | O16: 0 | P16: 0 | Q16: 0 | R16: 0 | S16: 0 | T16: 0 | U16: 0 | V16: 0 | W16: 0 | X16: 0 | Y16: 0 | Z16: 0 | AA16: 0 | AB16: 0 | AC16: 0 | AD16: 0 | AE16: 0 | AF16: 0 | AG16: 0 | AH16: 0 | AI16: 0 | AJ16: 0 | AK16: 0 | AL16: 0 | AM16: 0 | AN16: 0 | AO16: 0 | AP16: 0 | AQ16: 0 | AR16: 2.5 | AS16: 2.5 | AT16: 2.5 | AU16: 2.5 | AV16: 2.5 | AW16: 2.5 | AX16: 2.5 | AY16: 2.5 | AZ16: 2.5 | BA16: 5.9 | BB16: 10.542 | BC16: 10.542 | BD16: 10.542 | BE16: 10.542 | BF16: 10.542 | BG16: 10.542 | BH16: 10.542 | BI16: 10.542 | BJ16: 11.0691 | BK16: 11.0691 | BL16: 11.0691 | BM16: 11.0691 | BN16: 11.0691 | BO16: 11.0691 | BP16: 11.0691 | BQ16: 11.0691 | BR16: 11.0691 | BS16: 11.0691 | BT16: 11.0691 | BU16: 11.0691 | BV16: 11.622555 | BW16: 11.622555 | BX16: 11.622555 | BY16: 11.622555 | BZ16: 11.622555 | CA16: 11.622555 | CB16: 11.622555 | CC16: 11.622555 | CD16: 11.622555 | CE16: 11.622555 | CF16: 11.622555 | CG16: 11.622555 | CH16: 12.203683 | CI16: 12.203683 | CJ16: 12.203683 | CK16: 12.203683 | CL16: 12.203683 | CM16: 12.203683 | CN16: 12.203683 | CO16: 12.203683 | CP16: 12.203683 | CQ16: 12.203683 | CR16: 12.203683 | CS16: 12.203683 | CT16: 12.813867 | CU16: 12.813867 | CV16: 12.813867 | CW16: 12.813867 | CX16: 12.813867 | CY16: 12.813867 | CZ16: 12.813867 | DA16: 12.813867 | DB16: 12.813867 | DC16: 12.813867 | DD16: 12.813867 | DE16: 12.813867 | DF16: 0 | DG16: 0 | DH16: 0 | DI16: 0 | DJ16: 0 | DK16: 0 | DL16: 0 | DM16: 0 | DN16: 0 | DO16: 0 | DP16: 0 | DQ16: 0 | DR16: 0 | DT16: =+F16-E16 | DU16: =+G16-F16 | DV16: =+H16-G16 | DW16: =+I16-H16
B17: AAP | C17: Major | E17: =+SUMIFS($O17:$DR17,$O$7:$DR$7,E$7) | F17: =+SUMIFS($O17:$DR17,$O$7:$DR$7,F$7) | G17: =+SUMIFS($O17:$DR17,$O$7:$DR$7,G$7) | H17: =+SUMIFS($O17:$DR17,$O$7:$DR$7,H$7) | I17: =+SUMIFS($O17:$DR17,$O$7:$DR$7,I$7) | J17: =+SUMIFS($O17:$DR17,$O$7:$DR$7,J$7) | K17: =+SUMIFS($O17:$DR17,$O$7:$DR$7,K$7) | L17: =+SUMIFS($O17:$DR17,$O$7:$DR$7,L$7) | M17: =+SUMIFS($O17:$DR17,$O$7:$DR$7,M$7) | O17: 18.212 | P17: 18.212 | Q17: 18.212 | R17: 18.212 | S17: 18.212 | T17: 18.212 | U17: 18.212 | V17: 18.212 | W17: 18.212 | X17: 18.917 | Y17: 21.337 | Z17: 21.337 | AA17: 21.883 | AB17: 21.883 | AC17: 21.883 | AD17: 21.883 | AE17: 21.883 | AF17: 21.883 | AG17: 21.883 | AH17: 21.883 | AI17: 21.883 | AJ17: 21.883 | AK17: 23.072 | AL17: 22.508 | AM17: 23.071 | AN17: 23.071 | AO17: 23.071 | AP17: 23.071 | AQ17: 23.071 | AR17: 23.071 | AS17: 23.071 | AT17: 22.629 | AU17: 23.071 | AV17: 23.071 | AW17: 23.071 | AX17: 23.071 | AY17: 23.763 | AZ17: 23.763 | BA17: 23.763 | BB17: 23.763 | BC17: 23.763 | BD17: 23.763 | BE17: 23.763 | BF17: 23.763 | BG17: 23.763 | BH17: 23.763 | BI17: 23.763 | BJ17: 23.763 | BK17: 33.25 | BL17: 33.25 | BM17: 33.25 | BN17: 33.25 | BO17: 33.25 | BP17: 33.25 | BQ17: 33.25 | BR17: 33.25 | BS17: 33.25 | BT17: 33.25 | BU17: 33.25 | BV17: 33.25 | BW17: 34.2475 | BX17: 34.2475 | BY17: 34.2475 | BZ17: 34.2475 | CA17: 34.2475 | CB17: 34.2475 | CC17: 34.2475 | CD17: 34.2475 | CE17: 34.2475 | CF17: 34.2475 | CG17: 34.2475 | CH17: 34.2475 | CI17: 35.274925 | CJ17: 35.274925 | CK17: 35.274925 | CL17: 35.274925 | CM17: 35.274925 | CN17: 35.274925 | CO17: 35.274925 | CP17: 35.274925 | CQ17: 35.274925 | CR17: 35.274925 | CS17: 35.274925 | CT17: 35.274925 | CU17: 36.333173 | CV17: 36.333173 | CW17: 36.333173 | CX17: 36.333173 | CY17: 36.333173 | CZ17: 36.333173 | DA17: 36.333173 | DB17: 36.333173 | DC17: 36.333173 | DD17: 36.333173 | DE17: 36.333173 | DF17: 36.333173 | DG17: 37.423168 | DH17: 37.423168 | DI17: 37.423168 | DJ17: 37.423168 | DK17: 37.423168 | DL17: 37.423168 | DM17: 37.423168 | DN17: 37.423168 | DO17: 37.423168 | DP17: 37.423168 | DQ17: 37.423168 | DR17: 37.423168 | DT17: =+F17-E17 | DU17: =+G17-F17 | DV17: =+H17-G17 | DW17: =+I17-H17
B18: ADA | C18: Lower Middle Market | E18: =+SUMIFS($O18:$DR18,$O$7:$DR$7,E$7) | F18: =+SUMIFS($O18:$DR18,$O$7:$DR$7,F$7) | G18: =+SUMIFS($O18:$DR18,$O$7:$DR$7,G$7) | H18: =+SUMIFS($O18:$DR18,$O$7:$DR$7,H$7) | I18: =+SUMIFS($O18:$DR18,$O$7:$DR$7,I$7) | J18: =+SUMIFS($O18:$DR18,$O$7:$DR$7,J$7) | K18: =+SUMIFS($O18:$DR18,$O$7:$DR$7,K$7) | L18: =+SUMIFS($O18:$DR18,$O$7:$DR$7,L$7) | M18: =+SUMIFS($O18:$DR18,$O$7:$DR$7,M$7) | O18: 0 | P18: 0 | Q18: 0 | R18: 0 | S18: 0 | T18: 0 | U18: 0 | V18: 0 | W18: 0 | X18: 0 | Y18: 0 | Z18: 0 | AA18: 0 | AB18: 0 | AC18: 0 | AD18: 0 | AE18: 0 | AF18: 0 | AG18: 0 | AH18: 0 | AI18: 0 | AJ18: 0 | AK18: 0 | AL18: 0 | AM18: 0 | AN18: 0 | AO18: 0 | AP18: 0 | AQ18: 0 | AR18: 0 | AS18: 0 | AT18: 0 | AU18: 0 | AV18: 0 | AW18: 0 | AX18: 0 | AY18: 0 | AZ18: 0 | BA18: 0 | BB18: 0 | BC18: 4.805 | BD18: 4.805 | BE18: 4.805 | BF18: 4.805 | BG18: 4.805 | BH18: 4.805 | BI18: 4.805 | BJ18: 4.805 | BK18: 14.875 | BL18: 14.875 | BM18: 14.875 | BN18: 14.875 | BO18: 14.875 | BP18: 14.875 | BQ18: 14.875 | BR18: 14.875 | BS18: 14.875 | BT18: 14.875 | BU18: 14.875 | BV18: 14.875 | BW18: 15.32125 | BX18: 15.32125 | BY18: 15.32125 | BZ18: 15.32125 | CA18: 15.32125 | CB18: 15.32125 | CC18: 15.32125 | CD18: 15.32125 | CE18: 15.32125 | CF18: 15.32125 | CG18: 15.32125 | CH18: 15.32125 | CI18: 15.780888 | CJ18: 15.780888 | CK18: 15.780888 | CL18: 15.780888 | CM18: 15.780888 | CN18: 15.780888 | CO18: 15.780888 | CP18: 15.780888 | CQ18: 15.780888 | CR18: 15.780888 | CS18: 15.780888 | CT18: 15.780888 | CU18: 16.254314 | CV18: 16.254314 | CW18: 16.254314 | CX18: 16.254314 | CY18: 16.254314 | CZ18: 16.254314 | DA18: 16.254314 | DB18: 16.254314 | DC18: 16.254314 | DD18: 16.254314 | DE18: 16.254314 | DF18: 16.254314 | DG18: 16.741944 | DH18: 16.741944 | DI18: 16.741944 | DJ18: 16.741944 | DK18: 16.741944 | DL18: 16.741944 | DM18: 16.741944 | DN18: 16.741944 | DO18: 16.741944 | DP18: 16.741944 | DQ18: 16.741944 | DR18: 16.741944 | DT18: =+F18-E18 | DU18: =+G18-F18 | DV18: =+H18-G18 | DW18: =+I18-H18
B19: AHRQ | C19: Lower Middle Market | E19: =+SUMIFS($O19:$DR19,$O$7:$DR$7,E$7) | F19: =+SUMIFS($O19:$DR19,$O$7:$DR$7,F$7) | G19: =+SUMIFS($O19:$DR19,$O$7:$DR$7,G$7) | H19: =+SUMIFS($O19:$DR19,$O$7:$DR$7,H$7) | I19: =+SUMIFS($O19:$DR19,$O$7:$DR$7,I$7) | J19: =+SUMIFS($O19:$DR19,$O$7:$DR$7,J$7) | K19: =+SUMIFS($O19:$DR19,$O$7:$DR$7,K$7) | L19: =+SUMIFS($O19:$DR19,$O$7:$DR$7,L$7) | M19: =+SUMIFS($O19:$DR19,$O$7:$DR$7,M$7) | O19: 0 | P19: 0 | Q19: 0 | R19: 0 | S19: 0 | T19: 0 | U19: 0 | V19: 0 | W19: 0 | X19: 0 | Y19: 0 | Z19: 0 | AA19: 0 | AB19: 0 | AC19: 0 | AD19: 0 | AE19: 0 | AF19: 0 | AG19: 0 | AH19: 0 | AI19: 0 | AJ19: 0 | AK19: 0 | AL19: 0 | AM19: 0 | AN19: 0 | AO19: 0 | AP19: 0 | AQ19: 0 | AR19: 0 | AS19: 0 | AT19: 0 | AU19: 0 | AV19: 0 | AW19: 0 | AX19: 0 | AY19: 0 | AZ19: 0 | BA19: 0 | BB19: 0 | BC19: 0 | BD19: 0 | BE19: 0 | BF19: 0 | BG19: 0 | BH19: 0 | BI19: 0 | BJ19: 0 | BK19: 0 | BL19: 0 | BM19: 0 | BN19: 4.1666667 | BO19: 4.1666667 | BP19: 4.1666667 | BQ19: 4.1666667 | BR19: 4.1666667 | BS19: 4.1666667 | BT19: 4.1666667 | BU19: 4.1666667 | BV19: 4.1666667 | BW19: 4.1666667 | BX19: 4.1666667 | BY19: 4.1666667 | BZ19: 4.1666667 | CA19: 4.1666667 | CB19: 4.1666667 | CC19: 4.1666667 | CD19: 4.1666667 | CE19: 4.1666667 | CF19: 4.1666667 | CG19: 4.1666667 | CH19: 4.1666667 | CI19: 4.1666667 | CJ19: 4.1666667 | CK19: 4.1666667 | CL19: 0 | CM19: 0 | CN19: 0 | CO19: 0 | CP19: 0 | CQ19: 0 | CR19: 0 | CS19: 0 | CT19: 0 | CU19: 0 | CV19: 0 | CW19: 0 | CX19: 0 | CY19: 0 | CZ19: 0 | DA19: 0 | DB19: 0 | DC19: 0 | DD19: 0 | DE19: 0 | DF19: 0 | DG19: 0 | DH19: 0 | DI19: 0 | DJ19: 0 | DK19: 0 | DL19: 0 | DM19: 0 | DN19: 0 | DO19: 0 | DP19: 0 | DQ19: 0 | DR19: 0 | DT19: =+F19-E19 | DU19: =+G19-F19 | DV19: =+H19-G19 | DW19: =+I19-H19
B20: AIPP | C20: Major | E20: =+SUMIFS($O20:$DR20,$O$7:$DR$7,E$7) | F20: =+SUMIFS($O20:$DR20,$O$7:$DR$7,F$7) | G20: =+SUMIFS($O20:$DR20,$O$7:$DR$7,G$7) | H20: =+SUMIFS($O20:$DR20,$O$7:$DR$7,H$7) | I20: =+SUMIFS($O20:$DR20,$O$7:$DR$7,I$7) | J20: =+SUMIFS($O20:$DR20,$O$7:$DR$7,J$7) | K20: =+SUMIFS($O20:$DR20,$O$7:$DR$7,K$7) | L20: =+SUMIFS($O20:$DR20,$O$7:$DR$7,L$7) | M20: =+SUMIFS($O20:$DR20,$O$7:$DR$7,M$7) | O20: 0 | P20: 0 | Q20: 0 | R20: 0 | S20: 0 | T20: 0 | U20: 0 | V20: 0 | W20: 0 | X20: 0 | Y20: 0 | Z20: 0 | AA20: 0 | AB20: 0 | AC20: 0 | AD20: 0 | AE20: 0 | AF20: 0 | AG20: 0 | AH20: 0 | AI20: 0 | AJ20: 0 | AK20: 0 | AL20: 0 | AM20: 0 | AN20: 0 | AO20: 0 | AP20: 0 | AQ20: 0 | AR20: 0 | AS20: 0 | AT20: 0 | AU20: 0 | AV20: 0 | AW20: 0 | AX20: 0 | AY20: 0 | AZ20: 0 | BA20: 0 | BB20: 0 | BC20: 0 | BD20: 0 | BE20: 0 | BF20: 0 | BG20: 0 | BH20: 0 | BI20: 0 | BJ20: 0 | BK20: 0 | BL20: 0 | BM20: 5.805 | BN20: 5.805 | BO20: 5.805 | BP20: 5.805 | BQ20: 5.805 | BR20: 5.805 | BS20: 5.805 | BT20: 5.805 | BU20: 5.805 | BV20: 5.805 | BW20: 5.805 | BX20: 5.805 | BY20: 47.975 | BZ20: 47.975 | CA20: 47.975 | CB20: 47.975 | CC20: 47.975 | CD20: 47.975 | CE20: 47.975 | CF20: 47.975 | CG20: 47.975 | CH20: 47.975 | CI20: 47.975 | CJ20: 47.975 | CK20: 49.41425 | CL20: 49.41425 | CM20: 49.41425 | CN20: 49.41425 | CO20: 49.41425 | CP20: 49.41425 | CQ20: 49.41425 | CR20: 49.41425 | CS20: 49.41425 | CT20: 49.41425 | CU20: 49.41425 | CV20: 49.41425 | CW20: 50.896678 | CX20: 50.896678 | CY20: 50.896678 | CZ20: 50.896678 | DA20: 50.896678 | DB20: 50.896678 | DC20: 50.896678 | DD20: 50.896678 | DE20: 50.896678 | DF20: 50.896678 | DG20: 50.896678 | DH20: 50.896678 | DI20: 52.423578 | DJ20: 52.423578 | DK20: 52.423578 | DL20: 52.423578 | DM20: 52.423578 | DN20: 52.423578 | DO20: 52.423578 | DP20: 52.423578 | DQ20: 52.423578 | DR20: 52.423578 | DT20: =+F20-E20 | DU20: =+G20-F20 | DV20: =+H20-G20 | DW20: =+I20-H20
B21: ALLEN | C21: Upper Middle Market | E21: =+SUMIFS($O21:$DR21,$O$7:$DR$7,E$7) | F21: =+SUMIFS($O21:$DR21,$O$7:$DR$7,F$7) | G21: =+SUMIFS($O21:$DR21,$O$7:$DR$7,G$7) | H21: =+SUMIFS($O21:$DR21,$O$7:$DR$7,H$7) | I21: =+SUMIFS($O21:$DR21,$O$7:$DR$7,I$7) | J21: =+SUMIFS($O21:$DR21,$O$7:$DR$7,J$7) | K21: =+SUMIFS($O21:$DR21,$O$7:$DR$7,K$7) | L21: =+SUMIFS($O21:$DR21,$O$7:$DR$7,L$7) | M21: =+SUMIFS($O21:$DR21,$O$7:$DR$7,M$7) | O21: 0 | P21: 0 | Q21: 0 | R21: 0 | S21: 0 | T21: 0 | U21: 0 | V21: 0 | W21: 0 | X21: 0 | Y21: 0 | Z21: 0 | AA21: 0 | AB21: 0 | AC21: 0 | AD21: 0 | AE21: 0 | AF21: 0 | AG21: 0 | AH21: 0 | AI21: 0 | AJ21: 0 | AK21: 0 | AL21: 0 | AM21: 0 | AN21: 8.334 | AO21: 10.417 | AP21: 12.5 | AQ21: 14.584 | AR21: 16.666 | AS21: 16.666 | AT21: 16.666 | AU21: 13.963 | AV21: 16.667 | AW21: 16.666 | AX21: 113.912 | AY21: 16.66667 | AZ21: 16.66667 | BA21: 25.95967 | BB21: 16.66667 | BC21: 16.66667 | BD21: 33.82867 | BE21: 16.66667 | BF21: 16.66667 | BG21: 23.81767 | BH21: 16.66667 | BI21: 16.66667 | BJ21: 40.36067 | BK21: 16.66667 | BL21: 16.66667 | BM21: 30.69167 | BN21: 16.66667 | BO21: 16.66667 | BP21: 31.66667 | BQ21: 16.66667 | BR21: 16.66667 | BS21: 31.66667 | BT21: 16.66667 | BU21: 16.66667 | BV21: 31.66667 | BW21: 16.66667 | BX21: 16.66667 | BY21: 31.11242 | BZ21: 16.66667 | CA21: 16.66667 | CB21: 32.11667 | CC21: 16.66667 | CD21: 16.66667 | CE21: 32.11667 | CF21: 16.66667 | CG21: 16.66667 | CH21: 32.11667 | CI21: 16.66667 | CJ21: 16.66667 | CK21: 31.545793 | CL21: 16.66667 | CM21: 16.66667 | CN21: 32.58017 | CO21: 16.66667 | CP21: 16.66667 | CQ21: 32.58017 | CR21: 16.66667 | CS21: 16.66667 | CT21: 32.58017 | CU21: 16.66667 | CV21: 16.66667 | CW21: 31.992166 | CX21: 16.66667 | CY21: 16.66667 | CZ21: 33.057575 | DA21: 16.66667 | DB21: 16.66667 | DC21: 33.057575 | DD21: 16.66667 | DE21: 16.66667 | DF21: 33.057575 | DG21: 16.66667 | DH21: 16.66667 | DI21: 32.451931 | DJ21: 16.66667 | DK21: 16.66667 | DL21: 33.549302 | DM21: 16.66667 | DN21: 16.66667 | DO21: 33.549302 | DP21: 16.66667 | DQ21: 16.66667 | DR21: 33.549302 | DT21: =+F21-E21 | DU21: =+G21-F21 | DV21: =+H21-G21 | DW21: =+I21-H21
B22: AMA | C22: Mega | E22: =+SUMIFS($O22:$DR22,$O$7:$DR$7,E$7) | F22: =+SUMIFS($O22:$DR22,$O$7:$DR$7,F$7) | G22: =+SUMIFS($O22:$DR22,$O$7:$DR$7,G$7) | H22: =+SUMIFS($O22:$DR22,$O$7:$DR$7,H$7) | I22: =+SUMIFS($O22:$DR22,$O$7:$DR$7,I$7) | J22: =+SUMIFS($O22:$DR22,$O$7:$DR$7,J$7) | K22: =+SUMIFS($O22:$DR22,$O$7:$DR$7,K$7) | L22: =+SUMIFS($O22:$DR22,$O$7:$DR$7,L$7) | M22: =+SUMIFS($O22:$DR22,$O$7:$DR$7,M$7) | O22: 104.247 | P22: 104.247 | Q22: 104.247 | R22: 104.247 | S22: 107.22 | T22: 110.647 | U22: 110.647 | V22: 100.647 | W22: 110.647 | X22: 110.646 | Y22: 110.647 | Z22: 156.48 | AA22: 137.27 | AB22: 137.27 | AC22: 133.104 | AD22: 133.103 | AE22: 133.104 | AF22: 133.103 | AG22: 133.103 | AH22: 133.103 | AI22: 133.104 | AJ22: 134.104 | AK22: 133.104 | AL22: 133.104 | AM22: 137.208 | AN22: 137.208 | AO22: 137.208 | AP22: 137.208 | AQ22: 137.208 | AR22: 137.208 | AS22: 138.208 | AT22: 131.394 | AU22: 138.208 | AV22: 138.208 | AW22: 143.575 | AX22: 149.708 | AY22: 154.25563 | AZ22: 154.25563 | BA22: 154.25563 | BB22: 154.25563 | BC22: 154.25563 | BD22: 154.25563 | BE22: 154.25563 | BF22: 154.25563 | BG22: 154.25563 | BH22: 150.92229 | BI22: 151.29729 | BJ22: 151.29729 | BK22: 156.83067 | BL22: 156.83067 | BM22: 156.83067 | BN22: 156.83067 | BO22: 156.83067 | BP22: 156.83067 | BQ22: 156.83067 | BR22: 156.83067 | BS22: 156.83067 | BT22: 156.83067 | BU22: 157.21692 | BV22: 157.21692 | BW22: 161.19313 | BX22: 161.19313 | BY22: 161.19313 | BZ22: 161.19313 | CA22: 161.19313 | CB22: 161.19313 | CC22: 161.19313 | CD22: 161.19313 | CE22: 161.19313 | CF22: 161.19313 | CG22: 161.59097 | CH22: 161.59097 | CI22: 13.659088 | CJ22: 13.659088 | CK22: 13.659088 | CL22: 13.659088 | CM22: 13.659088 | CN22: 13.659088 | CO22: 13.659088 | CP22: 13.659088 | CQ22: 13.659088 | CR22: 13.659088 | CS22: 14.06886 | CT22: 14.06886 | CU22: 14.06886 | CV22: 14.06886 | CW22: 14.06886 | CX22: 14.06886 | CY22: 14.06886 | CZ22: 14.06886 | DA22: 14.06886 | DB22: 14.06886 | DC22: 14.06886 | DD22: 14.06886 | DE22: 14.490926 | DF22: 14.490926 | DG22: 0 | DH22: 0 | DI22: 0 | DJ22: 0 | DK22: 0 | DL22: 0 | DM22: 0 | DN22: 0 | DO22: 0 | DP22: 0 | DQ22: 0 | DR22: 0 | DT22: =+F22-E22 | DU22: =+G22-F22 | DV22: =+H22-G22 | DW22: =+I22-H22
